<?xml version="1.0" encoding="utf-8"?>
<!-- This URDF was automatically created by SolidWorks to URDF Exporter! Originally created by Stephen Brawner (brawner@gmail.com) 
     Commit Version: 1.6.0-4-g7f85cfe  Build Version: 1.6.7995.38578
     For more information, please see http://wiki.ros.org/sw_urdf_exporter -->
<robot
  name="Urdf_ConfigFiles">
  <link
    name="base_link">
    <inertial>
      <origin
        xyz="-0.00495925277676378 -3.90134842870204E-05 0.00279738369756694"
        rpy="0 0 0" />
      <mass
        value="0.118532698310348" />
      <inertia
        ixx="2.97417988958695E-05"
        ixy="1.96289279267123E-08"
        ixz="-3.18825711531161E-08"
        iyy="7.40672823931806E-05"
        iyz="2.6699219579544E-10"
        izz="9.60808739626506E-05" />
    </inertial>
    <visual>
      <origin
        xyz="0 0 0"
        rpy="0 0 0" />
      <geometry>
        <mesh
          filename="package://Urdf_ConfigFiles/meshes/base_link.STL" />
      </geometry>
      <material
        name="">
        <color
          rgba="0.752941176470588 0.752941176470588 0.752941176470588 1" />
      </material>
    </visual>
    <collision>
      <origin
        xyz="0 0 0"
        rpy="0 0 0" />
      <geometry>
        <mesh
          filename="package://Urdf_ConfigFiles/meshes/base_link.STL" />
      </geometry>
    </collision>
  </link>
  <link
    name="RM_JIAN_LINK">
    <inertial>
      <origin
        xyz="0.0187543594677149 -0.000379261050061135 0.000812950598078848"
        rpy="0 0 0" />
      <mass
        value="0.00699822854338534" />
      <inertia
        ixx="9.5610462415327E-07"
        ixy="-3.93695610685643E-10"
        ixz="-7.71981360447323E-11"
        iyy="6.83941781535081E-07"
        iyz="5.4014319561666E-12"
        izz="6.84612495216708E-07" />
    </inertial>
    <visual>
      <origin
        xyz="0 0 0"
        rpy="0 0 0" />
      <geometry>
        <mesh
          filename="package://Urdf_ConfigFiles/meshes/RM_JIAN_LINK.STL" />
      </geometry>
      <material
        name="">
        <color
          rgba="0.752941176470588 0.752941176470588 0.752941176470588 1" />
      </material>
    </visual>
    <collision>
      <origin
        xyz="0 0 0"
        rpy="0 0 0" />
      <geometry>
        <mesh
          filename="package://Urdf_ConfigFiles/meshes/RM_JIAN_LINK.STL" />
      </geometry>
    </collision>
  </link>
  <joint
    name="RM_JIAN_JOINT"
    type="revolute">
    <origin
      xyz="0 -0.050828 0.0045"
      rpy="0 0 -1.5708" />
    <parent
      link="base_link" />
    <child
      link="RM_JIAN_LINK" />
    <axis
      xyz="0 0 1" />
    <limit
      lower="-1.5708"
      upper="1.5708"
      effort="0"
      velocity="0" />
  </joint>
  <link
    name="RM_ZHOU_LINK">
    <inertial>
      <origin
        xyz="0.0212109550888898 -1.20022572680017E-05 0.00316734503657168"
        rpy="0 0 0" />
      <mass
        value="0.023428071079214" />
      <inertia
        ixx="1.44008103643533E-06"
        ixy="7.11079687137408E-13"
        ixz="1.11808960635764E-14"
        iyy="3.27271769052332E-06"
        iyz="-5.61999736575962E-15"
        izz="2.55442792425579E-06" />
    </inertial>
    <visual>
      <origin
        xyz="0 0 0"
        rpy="0 0 0" />
      <geometry>
        <mesh
          filename="package://Urdf_ConfigFiles/meshes/RM_ZHOU_LINK.STL" />
      </geometry>
      <material
        name="">
        <color
          rgba="0.752941176470588 0.752941176470588 0.752941176470588 1" />
      </material>
    </visual>
    <collision>
      <origin
        xyz="0 0 0"
        rpy="0 0 0" />
      <geometry>
        <mesh
          filename="package://Urdf_ConfigFiles/meshes/RM_ZHOU_LINK.STL" />
      </geometry>
    </collision>
  </link>
  <joint
    name="RM_ZHOU_JOINT"
    type="revolute">
    <origin
      xyz="0.039955 0.0049 0.0001"
      rpy="1.5708 0 0" />
    <parent
      link="RM_JIAN_LINK" />
    <child
      link="RM_ZHOU_LINK" />
    <axis
      xyz="0 0 1" />
    <limit
      lower="-1.5708"
      upper="1.5708"
      effort="0"
      velocity="0" />
  </joint>
  <link
    name="RM_XI_LINK">
    <inertial>
      <origin
        xyz="0.0466384686418486 -7.84327888617709E-05 0.000588778480515891"
        rpy="0 0 0" />
      <mass
        value="0.00724422080433269" />
      <inertia
        ixx="4.47759491491986E-07"
        ixy="-3.05207207854443E-11"
        ixz="-3.89529951404105E-10"
        iyy="3.11680934014267E-06"
        iyz="5.401367042749E-12"
        izz="2.82563849115435E-06" />
    </inertial>
    <visual>
      <origin
        xyz="0 0 0"
        rpy="0 0 0" />
      <geometry>
        <mesh
          filename="package://Urdf_ConfigFiles/meshes/RM_XI_LINK.STL" />
      </geometry>
      <material
        name="">
        <color
          rgba="0.752941176470588 0.752941176470588 0.752941176470588 1" />
      </material>
    </visual>
    <collision>
      <origin
        xyz="0 0 0"
        rpy="0 0 0" />
      <geometry>
        <mesh
          filename="package://Urdf_ConfigFiles/meshes/RM_XI_LINK.STL" />
      </geometry>
    </collision>
  </link>
  <joint
    name="RM_XI_JOINT"
    type="revolute">
    <origin
      xyz="0.043146 0 0.004675"
      rpy="0 0 -1.5708" />
    <parent
      link="RM_ZHOU_LINK" />
    <child
      link="RM_XI_LINK" />
    <axis
      xyz="0 0 1" />
    <limit
      lower="-1.5708"
      upper="1.5708"
      effort="0"
      velocity="0" />
  </joint>
  <link
    name="RM_R_LINK">
    <inertial>
      <origin
        xyz="-6.88468379528295E-18 0 -1.38777878078145E-17"
        rpy="0 0 0" />
      <mass
        value="5.23598775598299E-07" />
      <inertia
        ixx="5.23598775598299E-14"
        ixy="0"
        ixz="0"
        iyy="5.23598775598299E-14"
        iyz="0"
        izz="5.23598775598299E-14" />
    </inertial>
    <visual>
      <origin
        xyz="0 0 0"
        rpy="0 0 0" />
      <geometry>
        <mesh
          filename="package://Urdf_ConfigFiles/meshes/RM_R_LINK.STL" />
      </geometry>
      <material
        name="">
        <color
          rgba="1 1 1 1" />
      </material>
    </visual>
    <collision>
      <origin
        xyz="0 0 0"
        rpy="0 0 0" />
      <geometry>
        <mesh
          filename="package://Urdf_ConfigFiles/meshes/RM_R_LINK.STL" />
      </geometry>
    </collision>
  </link>
  <joint
    name="RM_R_JOINT"
    type="revolute">
    <origin
      xyz="0.10465 -5E-05 0"
      rpy="3.1416 1.5708 0" />
    <parent
      link="RM_XI_LINK" />
    <child
      link="RM_R_LINK" />
    <axis
      xyz="0 0 -1" />
    <limit
      lower="-1.5708"
      upper="1.5708"
      effort="0"
      velocity="0" />
  </joint>
  <link
    name="RM_P_LINK">
    <inertial>
      <origin
        xyz="1.38777878078145E-17 -2.77555756156289E-17 -6.88468379528295E-18"
        rpy="0 0 0" />
      <mass
        value="5.23598775598299E-07" />
      <inertia
        ixx="5.23598775598299E-14"
        ixy="-6.68116840734896E-33"
        ixz="-1.55575381946529E-61"
        iyy="5.23598775598299E-14"
        iyz="-2.18952885050753E-47"
        izz="5.23598775598299E-14" />
    </inertial>
    <visual>
      <origin
        xyz="0 0 0"
        rpy="0 0 0" />
      <geometry>
        <mesh
          filename="package://Urdf_ConfigFiles/meshes/RM_P_LINK.STL" />
      </geometry>
      <material
        name="">
        <color
          rgba="1 1 1 1" />
      </material>
    </visual>
    <collision>
      <origin
        xyz="0 0 0"
        rpy="0 0 0" />
      <geometry>
        <mesh
          filename="package://Urdf_ConfigFiles/meshes/RM_P_LINK.STL" />
      </geometry>
    </collision>
  </link>
  <joint
    name="RM_P_JOINT"
    type="revolute">
    <origin
      xyz="0 0 0"
      rpy="0 1.5708 0" />
    <parent
      link="RM_R_LINK" />
    <child
      link="RM_P_LINK" />
    <axis
      xyz="0 0 1" />
    <limit
      lower="-1.5708"
      upper="1.5708"
      effort="0"
      velocity="0" />
  </joint>
  <link
    name="RM_Y_LINK">
    <inertial>
      <origin
        xyz="1.38777878078145E-17 -9.05308814025396E-18 5.55111512312578E-17"
        rpy="0 0 0" />
      <mass
        value="5.23598775598299E-07" />
      <inertia
        ixx="5.23598775598299E-14"
        ixy="0"
        ixz="0"
        iyy="5.23598775598299E-14"
        iyz="-2.18952885050753E-47"
        izz="5.23598775598299E-14" />
    </inertial>
    <visual>
      <origin
        xyz="0 0 0"
        rpy="0 0 0" />
      <geometry>
        <mesh
          filename="package://Urdf_ConfigFiles/meshes/RM_Y_LINK.STL" />
      </geometry>
      <material
        name="">
        <color
          rgba="1 1 1 1" />
      </material>
    </visual>
    <collision>
      <origin
        xyz="0 0 0"
        rpy="0 0 0" />
      <geometry>
        <mesh
          filename="package://Urdf_ConfigFiles/meshes/RM_Y_LINK.STL" />
      </geometry>
    </collision>
  </link>
  <joint
    name="RM_Y_JOINT"
    type="revolute">
    <origin
      xyz="0 0 0"
      rpy="1.5708 0 0" />
    <parent
      link="RM_P_LINK" />
    <child
      link="RM_Y_LINK" />
    <axis
      xyz="0 0 -1" />
    <limit
      lower="-1.5708"
      upper="1.5708"
      effort="0"
      velocity="0" />
  </joint>
  <link
    name="RF_JIAN_LINK">
    <inertial>
      <origin
        xyz="0.0187543594239746 -0.000379261041653148 0.000812950580056213"
        rpy="0 0 0" />
      <mass
        value="0.006998228698532" />
      <inertia
        ixx="9.56104624157523E-07"
        ixy="-3.93695610685637E-10"
        ixz="-7.71981360447407E-11"
        iyy="6.83941781705483E-07"
        iyz="5.40143195606536E-12"
        izz="6.84612495387111E-07" />
    </inertial>
    <visual>
      <origin
        xyz="0 0 0"
        rpy="0 0 0" />
      <geometry>
        <mesh
          filename="package://Urdf_ConfigFiles/meshes/RF_JIAN_LINK.STL" />
      </geometry>
      <material
        name="">
        <color
          rgba="0.752941176470588 0.752941176470588 0.752941176470588 1" />
      </material>
    </visual>
    <collision>
      <origin
        xyz="0 0 0"
        rpy="0 0 0" />
      <geometry>
        <mesh
          filename="package://Urdf_ConfigFiles/meshes/RF_JIAN_LINK.STL" />
      </geometry>
    </collision>
  </link>
  <joint
    name="RF_JIAN_JOINT"
    type="revolute">
    <origin
      xyz="0.077746 -0.036979 0.0047"
      rpy="0 0 -0.7854" />
    <parent
      link="base_link" />
    <child
      link="RF_JIAN_LINK" />
    <axis
      xyz="0 0 1" />
    <limit
      lower="-1.5708"
      upper="1.5708"
      effort="0"
      velocity="0" />
  </joint>
  <link
    name="RF_ZHOU_LINK">
    <inertial>
      <origin
        xyz="0.0212109520763576 -1.20023545394973E-05 0.00316723430018339"
        rpy="0 0 0" />
      <mass
        value="0.0234278880986834" />
      <inertia
        ixx="1.44006193707477E-06"
        ixy="-4.51032339993588E-12"
        ixz="1.20700056225565E-14"
        iyy="3.27264695060537E-06"
        iyz="-5.77126578240722E-15"
        izz="2.55438959466493E-06" />
    </inertial>
    <visual>
      <origin
        xyz="0 0 0"
        rpy="0 0 0" />
      <geometry>
        <mesh
          filename="package://Urdf_ConfigFiles/meshes/RF_ZHOU_LINK.STL" />
      </geometry>
      <material
        name="">
        <color
          rgba="0.752941176470588 0.752941176470588 0.752941176470588 1" />
      </material>
    </visual>
    <collision>
      <origin
        xyz="0 0 0"
        rpy="0 0 0" />
      <geometry>
        <mesh
          filename="package://Urdf_ConfigFiles/meshes/RF_ZHOU_LINK.STL" />
      </geometry>
    </collision>
  </link>
  <joint
    name="RF_ZHOU_JOINT"
    type="revolute">
    <origin
      xyz="0.03995 0.0047 0"
      rpy="1.5708 0 0" />
    <parent
      link="RF_JIAN_LINK" />
    <child
      link="RF_ZHOU_LINK" />
    <axis
      xyz="0 0 1" />
    <limit
      lower="-1.5708"
      upper="1.5708"
      effort="0"
      velocity="0" />
  </joint>
  <link
    name="RF_XI_LINK">
    <inertial>
      <origin
        xyz="0.0466384689069635 -7.84328003208545E-05 0.000588778477364212"
        rpy="0 0 0" />
      <mass
        value="0.00724422084311935" />
      <inertia
        ixx="4.47759491534585E-07"
        ixy="-3.05207207857134E-11"
        ixz="-3.89529951428146E-10"
        iyy="3.11680934014373E-06"
        iyz="5.40136700286257E-12"
        izz="2.82563849119695E-06" />
    </inertial>
    <visual>
      <origin
        xyz="0 0 0"
        rpy="0 0 0" />
      <geometry>
        <mesh
          filename="package://Urdf_ConfigFiles/meshes/RF_XI_LINK.STL" />
      </geometry>
      <material
        name="">
        <color
          rgba="0.752941176470588 0.752941176470588 0.752941176470588 1" />
      </material>
    </visual>
    <collision>
      <origin
        xyz="0 0 0"
        rpy="0 0 0" />
      <geometry>
        <mesh
          filename="package://Urdf_ConfigFiles/meshes/RF_XI_LINK.STL" />
      </geometry>
    </collision>
  </link>
  <joint
    name="RF_XI_JOINT"
    type="revolute">
    <origin
      xyz="0.043146 0 0.004675"
      rpy="0 0 -1.5708" />
    <parent
      link="RF_ZHOU_LINK" />
    <child
      link="RF_XI_LINK" />
    <axis
      xyz="0 0 1" />
    <limit
      lower="-1.5708"
      upper="1.5708"
      effort="0"
      velocity="0" />
  </joint>
  <link
    name="RF_R_LINK">
    <inertial>
      <origin
        xyz="5.55111512312578E-17 -1.23512311489549E-15 1.17961196366423E-15"
        rpy="0 0 0" />
      <mass
        value="5.23598775598299E-07" />
      <inertia
        ixx="5.23598775598299E-14"
        ixy="0"
        ixz="0"
        iyy="5.23598775598299E-14"
        iyz="0"
        izz="5.23598775598299E-14" />
    </inertial>
    <visual>
      <origin
        xyz="0 0 0"
        rpy="0 0 0" />
      <geometry>
        <mesh
          filename="package://Urdf_ConfigFiles/meshes/RF_R_LINK.STL" />
      </geometry>
      <material
        name="">
        <color
          rgba="1 1 1 1" />
      </material>
    </visual>
    <collision>
      <origin
        xyz="0 0 0"
        rpy="0 0 0" />
      <geometry>
        <mesh
          filename="package://Urdf_ConfigFiles/meshes/RF_R_LINK.STL" />
      </geometry>
    </collision>
  </link>
  <joint
    name="RF_R_JOINT"
    type="revolute">
    <origin
      xyz="0.10465 -5E-05 0"
      rpy="-1.5708 0.7854 1.5708" />
    <parent
      link="RF_XI_LINK" />
    <child
      link="RF_R_LINK" />
    <axis
      xyz="0 0 1" />
    <limit
      lower="-1.5708"
      upper="1.5708"
      effort="0"
      velocity="0" />
  </joint>
  <link
    name="RF_P_LINK">
    <inertial>
      <origin
        xyz="-7.35522753814166E-16 -7.07767178198537E-16 5.55111512312578E-17"
        rpy="0 0 0" />
      <mass
        value="5.23598775598299E-07" />
      <inertia
        ixx="5.23598775598299E-14"
        ixy="-1.33623368146977E-32"
        ixz="-3.11150763893057E-61"
        iyy="5.23598775598299E-14"
        iyz="-2.18952885050753E-47"
        izz="5.23598775598299E-14" />
    </inertial>
    <visual>
      <origin
        xyz="0 0 0"
        rpy="0 0 0" />
      <geometry>
        <mesh
          filename="package://Urdf_ConfigFiles/meshes/RF_P_LINK.STL" />
      </geometry>
      <material
        name="">
        <color
          rgba="1 1 1 1" />
      </material>
    </visual>
    <collision>
      <origin
        xyz="0 0 0"
        rpy="0 0 0" />
      <geometry>
        <mesh
          filename="package://Urdf_ConfigFiles/meshes/RF_P_LINK.STL" />
      </geometry>
    </collision>
  </link>
  <joint
    name="RF_P_LINK"
    type="revolute">
    <origin
      xyz="0 0 0"
      rpy="0 1.5708 0" />
    <parent
      link="RF_R_LINK" />
    <child
      link="RF_P_LINK" />
    <axis
      xyz="0 0 1" />
    <limit
      lower="-1.5708"
      upper="1.5708"
      effort="0"
      velocity="0" />
  </joint>
  <link
    name="RF_Y_LINK">
    <inertial>
      <origin
        xyz="-1.17961196366423E-15 5.55111512312578E-17 1.23512311489549E-15"
        rpy="0 0 0" />
      <mass
        value="5.23598775598299E-07" />
      <inertia
        ixx="5.23598775598299E-14"
        ixy="0"
        ixz="-7.59645419660809E-62"
        iyy="5.23598775598299E-14"
        iyz="1.87267054187694E-93"
        izz="5.23598775598299E-14" />
    </inertial>
    <visual>
      <origin
        xyz="0 0 0"
        rpy="0 0 0" />
      <geometry>
        <mesh
          filename="package://Urdf_ConfigFiles/meshes/RF_Y_LINK.STL" />
      </geometry>
      <material
        name="">
        <color
          rgba="1 1 1 1" />
      </material>
    </visual>
    <collision>
      <origin
        xyz="0 0 0"
        rpy="0 0 0" />
      <geometry>
        <mesh
          filename="package://Urdf_ConfigFiles/meshes/RF_Y_LINK.STL" />
      </geometry>
    </collision>
  </link>
  <joint
    name="RF_Y_JOINT"
    type="revolute">
    <origin
      xyz="0 0 0"
      rpy="1.5708 0 0" />
    <parent
      link="RF_P_LINK" />
    <child
      link="RF_Y_LINK" />
    <axis
      xyz="0 0 -1" />
    <limit
      lower="-1.5708"
      upper="1.5708"
      effort="0"
      velocity="0" />
  </joint>
  <link
    name="LF_JIAN_LINK">
    <inertial>
      <origin
        xyz="0.0187543594239746 -0.000379261041653173 0.000812950580056271"
        rpy="0 0 0" />
      <mass
        value="0.006998228698532" />
      <inertia
        ixx="9.56104624157522E-07"
        ixy="-3.9369561068569E-10"
        ixz="-7.71981360439546E-11"
        iyy="6.83941781705483E-07"
        iyz="5.40143195614686E-12"
        izz="6.8461249538711E-07" />
    </inertial>
    <visual>
      <origin
        xyz="0 0 0"
        rpy="0 0 0" />
      <geometry>
        <mesh
          filename="package://Urdf_ConfigFiles/meshes/LF_JIAN_LINK.STL" />
      </geometry>
      <material
        name="">
        <color
          rgba="0.752941176470588 0.752941176470588 0.752941176470588 1" />
      </material>
    </visual>
    <collision>
      <origin
        xyz="0 0 0"
        rpy="0 0 0" />
      <geometry>
        <mesh
          filename="package://Urdf_ConfigFiles/meshes/LF_JIAN_LINK.STL" />
      </geometry>
    </collision>
  </link>
  <joint
    name="LF_JIAN_JOINT"
    type="revolute">
    <origin
      xyz="0.077746 0.036979 0.0047"
      rpy="0 0 0.7854" />
    <parent
      link="base_link" />
    <child
      link="LF_JIAN_LINK" />
    <axis
      xyz="0 0 1" />
    <limit
      lower="-1.5708"
      upper="1.5708"
      effort="0"
      velocity="0" />
  </joint>
  <link
    name="LF_ZHOU_LINK">
    <inertial>
      <origin
        xyz="0.0212109520763105 -1.20023545296362E-05 0.00316723430032838"
        rpy="0 0 0" />
      <mass
        value="0.0234278880989933" />
      <inertia
        ixx="1.44006193710144E-06"
        ixy="-4.51031569642036E-12"
        ixz="1.20666170143106E-14"
        iyy="3.27264695063795E-06"
        iyz="-5.77408521079948E-15"
        izz="2.55438959467984E-06" />
    </inertial>
    <visual>
      <origin
        xyz="0 0 0"
        rpy="0 0 0" />
      <geometry>
        <mesh
          filename="package://Urdf_ConfigFiles/meshes/LF_ZHOU_LINK.STL" />
      </geometry>
      <material
        name="">
        <color
          rgba="0.752941176470588 0.752941176470588 0.752941176470588 1" />
      </material>
    </visual>
    <collision>
      <origin
        xyz="0 0 0"
        rpy="0 0 0" />
      <geometry>
        <mesh
          filename="package://Urdf_ConfigFiles/meshes/LF_ZHOU_LINK.STL" />
      </geometry>
    </collision>
  </link>
  <joint
    name="LF_ZHOU_JOINT"
    type="revolute">
    <origin
      xyz="0.03995 0.0047 0"
      rpy="1.5708 0 0" />
    <parent
      link="LF_JIAN_LINK" />
    <child
      link="LF_ZHOU_LINK" />
    <axis
      xyz="0 0 1" />
    <limit
      lower="-1.5708"
      upper="1.5708"
      effort="0"
      velocity="0" />
  </joint>
  <link
    name="LF_XI_LINK">
    <inertial>
      <origin
        xyz="0.046638468906964 -2.84328003209711E-05 0.000588778477360656"
        rpy="0 0 0" />
      <mass
        value="0.00724422084311936" />
      <inertia
        ixx="4.47759491534586E-07"
        ixy="-3.05207207856908E-11"
        ixz="-3.89529951402964E-10"
        iyy="3.11680934014374E-06"
        iyz="5.40136704277916E-12"
        izz="2.82563849119696E-06" />
    </inertial>
    <visual>
      <origin
        xyz="0 0 0"
        rpy="0 0 0" />
      <geometry>
        <mesh
          filename="package://Urdf_ConfigFiles/meshes/LF_XI_LINK.STL" />
      </geometry>
      <material
        name="">
        <color
          rgba="0.752941176470588 0.752941176470588 0.752941176470588 1" />
      </material>
    </visual>
    <collision>
      <origin
        xyz="0 0 0"
        rpy="0 0 0" />
      <geometry>
        <mesh
          filename="package://Urdf_ConfigFiles/meshes/LF_XI_LINK.STL" />
      </geometry>
    </collision>
  </link>
  <joint
    name="LF_XI_JOINT"
    type="revolute">
    <origin
      xyz="0.043096 0 0.004675"
      rpy="0 0 -1.5708" />
    <parent
      link="LF_ZHOU_LINK" />
    <child
      link="LF_XI_LINK" />
    <axis
      xyz="0 0 1" />
    <limit
      lower="-1.5708"
      upper="1.5708"
      effort="0"
      velocity="0" />
  </joint>
  <link
    name="LF_R_LINK">
    <inertial>
      <origin
        xyz="5.55111512312578E-17 2.77555756156289E-17 4.16333634234434E-17"
        rpy="0 0 0" />
      <mass
        value="5.23598775598299E-07" />
      <inertia
        ixx="5.23598775598299E-14"
        ixy="-1.46626343100792E-72"
        ixz="0"
        iyy="5.23598775598299E-14"
        iyz="0"
        izz="5.23598775598299E-14" />
    </inertial>
    <visual>
      <origin
        xyz="0 0 0"
        rpy="0 0 0" />
      <geometry>
        <mesh
          filename="package://Urdf_ConfigFiles/meshes/LF_R_LINK.STL" />
      </geometry>
      <material
        name="">
        <color
          rgba="1 1 1 1" />
      </material>
    </visual>
    <collision>
      <origin
        xyz="0 0 0"
        rpy="0 0 0" />
      <geometry>
        <mesh
          filename="package://Urdf_ConfigFiles/meshes/LF_R_LINK.STL" />
      </geometry>
    </collision>
  </link>
  <joint
    name="LF_R_JOINT"
    type="revolute">
    <origin
      xyz="0.10465 0 0"
      rpy="-1.5708 -0.7854 1.5708" />
    <parent
      link="LF_XI_LINK" />
    <child
      link="LF_R_LINK" />
    <axis
      xyz="0 0 -1" />
    <limit
      lower="-1.5708"
      upper="1.5708"
      effort="0"
      velocity="0" />
  </joint>
  <link
    name="LF_P_LINK">
    <inertial>
      <origin
        xyz="-4.16333634234434E-17 2.77555756156289E-17 5.55111512312578E-17"
        rpy="0 0 0" />
      <mass
        value="5.23598775598299E-07" />
      <inertia
        ixx="5.23598775598299E-14"
        ixy="1.12284965133098E-45"
        ixz="-9.28514645213293E-47"
        iyy="5.23598775598299E-14"
        iyz="6.07153216591882E-31"
        izz="5.23598775598299E-14" />
    </inertial>
    <visual>
      <origin
        xyz="0 0 0"
        rpy="0 0 0" />
      <geometry>
        <mesh
          filename="package://Urdf_ConfigFiles/meshes/LF_P_LINK.STL" />
      </geometry>
      <material
        name="">
        <color
          rgba="1 1 1 1" />
      </material>
    </visual>
    <collision>
      <origin
        xyz="0 0 0"
        rpy="0 0 0" />
      <geometry>
        <mesh
          filename="package://Urdf_ConfigFiles/meshes/LF_P_LINK.STL" />
      </geometry>
    </collision>
  </link>
  <joint
    name="LF_P_JOINT"
    type="revolute">
    <origin
      xyz="0 0 0"
      rpy="0 1.5708 0" />
    <parent
      link="LF_R_LINK" />
    <child
      link="LF_P_LINK" />
    <axis
      xyz="0 0 -1" />
    <limit
      lower="-1.5708"
      upper="1.5708"
      effort="0"
      velocity="0" />
  </joint>
  <link
    name="LF_Y_LINK">
    <inertial>
      <origin
        xyz="0 2.77555756156289E-17 -1.38777878078145E-17"
        rpy="0 0 0" />
      <mass
        value="5.23598775598299E-07" />
      <inertia
        ixx="5.23598775598299E-14"
        ixy="0"
        ixz="0"
        iyy="5.23598775598299E-14"
        iyz="1.46626343100792E-72"
        izz="5.23598775598299E-14" />
    </inertial>
    <visual>
      <origin
        xyz="0 0 0"
        rpy="0 0 0" />
      <geometry>
        <mesh
          filename="package://Urdf_ConfigFiles/meshes/LF_Y_LINK.STL" />
      </geometry>
      <material
        name="">
        <color
          rgba="1 1 1 1" />
      </material>
    </visual>
    <collision>
      <origin
        xyz="0 0 0"
        rpy="0 0 0" />
      <geometry>
        <mesh
          filename="package://Urdf_ConfigFiles/meshes/LF_Y_LINK.STL" />
      </geometry>
    </collision>
  </link>
  <joint
    name="LF_Y_JOINT"
    type="revolute">
    <origin
      xyz="0 0 0"
      rpy="1.5708 0 0" />
    <parent
      link="LF_P_LINK" />
    <child
      link="LF_Y_LINK" />
    <axis
      xyz="0 0 -1" />
    <limit
      lower="-1.5708"
      upper="1.5708"
      effort="0"
      velocity="0" />
  </joint>
  <link
    name="LM_JIAN_LINK">
    <inertial>
      <origin
        xyz="0.0187543594677149 -0.000379261050061133 0.000812950598078908"
        rpy="0 0 0" />
      <mass
        value="0.00699822854338534" />
      <inertia
        ixx="9.5610462415327E-07"
        ixy="-3.93695610685641E-10"
        ixz="-7.71981360440999E-11"
        iyy="6.83941781535081E-07"
        iyz="5.40143195618265E-12"
        izz="6.84612495216709E-07" />
    </inertial>
    <visual>
      <origin
        xyz="0 0 0"
        rpy="0 0 0" />
      <geometry>
        <mesh
          filename="package://Urdf_ConfigFiles/meshes/LM_JIAN_LINK.STL" />
      </geometry>
      <material
        name="">
        <color
          rgba="0.752941176470588 0.752941176470588 0.752941176470588 1" />
      </material>
    </visual>
    <collision>
      <origin
        xyz="0 0 0"
        rpy="0 0 0" />
      <geometry>
        <mesh
          filename="package://Urdf_ConfigFiles/meshes/LM_JIAN_LINK.STL" />
      </geometry>
    </collision>
  </link>
  <joint
    name="LM_JIAN_JOINT"
    type="revolute">
    <origin
      xyz="0 0.050828 0.0047"
      rpy="0 0 1.5708" />
    <parent
      link="base_link" />
    <child
      link="LM_JIAN_LINK" />
    <axis
      xyz="0 0 1" />
    <limit
      lower="-1.5708"
      upper="1.5708"
      effort="0"
      velocity="0" />
  </joint>
  <link
    name="LM_ZHOU_LINK">
    <inertial>
      <origin
        xyz="0.0212109550892057 -1.20022572315239E-05 0.00316734503662596"
        rpy="0 0 0" />
      <mass
        value="0.0234280710793364" />
      <inertia
        ixx="1.44008103644432E-06"
        ixy="7.11091725844634E-13"
        ixz="1.11688116052365E-14"
        iyy="3.27271769054075E-06"
        iyz="-5.62577642121198E-15"
        izz="2.55442792426713E-06" />
    </inertial>
    <visual>
      <origin
        xyz="0 0 0"
        rpy="0 0 0" />
      <geometry>
        <mesh
          filename="package://Urdf_ConfigFiles/meshes/LM_ZHOU_LINK.STL" />
      </geometry>
      <material
        name="">
        <color
          rgba="0.752941176470588 0.752941176470588 0.752941176470588 1" />
      </material>
    </visual>
    <collision>
      <origin
        xyz="0 0 0"
        rpy="0 0 0" />
      <geometry>
        <mesh
          filename="package://Urdf_ConfigFiles/meshes/LM_ZHOU_LINK.STL" />
      </geometry>
    </collision>
  </link>
  <joint
    name="LM_ZHOU_JOINT"
    type="revolute">
    <origin
      xyz="0.03995 0.0047 0"
      rpy="1.5708 0 0" />
    <parent
      link="LM_JIAN_LINK" />
    <child
      link="LM_ZHOU_LINK" />
    <axis
      xyz="0 0 1" />
    <limit
      lower="-1.5708"
      upper="1.5708"
      effort="0"
      velocity="0" />
  </joint>
  <link
    name="LM_XI_LINK">
    <inertial>
      <origin
        xyz="0.0466384686418475 -2.84327888619151E-05 0.000588778480513147"
        rpy="0 0 0" />
      <mass
        value="0.00724422080433268" />
      <inertia
        ixx="4.47759491491984E-07"
        ixy="-3.05207207853711E-11"
        ixz="-3.89529951404096E-10"
        iyy="3.11680934014266E-06"
        iyz="5.40136704276145E-12"
        izz="2.82563849115434E-06" />
    </inertial>
    <visual>
      <origin
        xyz="0 0 0"
        rpy="0 0 0" />
      <geometry>
        <mesh
          filename="package://Urdf_ConfigFiles/meshes/LM_XI_LINK.STL" />
      </geometry>
      <material
        name="">
        <color
          rgba="0.752941176470588 0.752941176470588 0.752941176470588 1" />
      </material>
    </visual>
    <collision>
      <origin
        xyz="0 0 0"
        rpy="0 0 0" />
      <geometry>
        <mesh
          filename="package://Urdf_ConfigFiles/meshes/LM_XI_LINK.STL" />
      </geometry>
    </collision>
  </link>
  <joint
    name="LM_XI_JOINT"
    type="revolute">
    <origin
      xyz="0.043096 0 0.004675"
      rpy="0 0 -1.5708" />
    <parent
      link="LM_ZHOU_LINK" />
    <child
      link="LM_XI_LINK" />
    <axis
      xyz="0 0 1" />
    <limit
      lower="-1.5708"
      upper="1.5708"
      effort="0"
      velocity="0" />
  </joint>
  <link
    name="LM_R_LINK">
    <inertial>
      <origin
        xyz="-3.3881317890172E-21 0 0"
        rpy="0 0 0" />
      <mass
        value="5.23598775598299E-07" />
      <inertia
        ixx="5.23598775598299E-14"
        ixy="-1.46626343100792E-72"
        ixz="0"
        iyy="5.23598775598299E-14"
        iyz="0"
        izz="5.23598775598299E-14" />
    </inertial>
    <visual>
      <origin
        xyz="0 0 0"
        rpy="0 0 0" />
      <geometry>
        <mesh
          filename="package://Urdf_ConfigFiles/meshes/LM_R_LINK.STL" />
      </geometry>
      <material
        name="">
        <color
          rgba="1 1 1 1" />
      </material>
    </visual>
    <collision>
      <origin
        xyz="0 0 0"
        rpy="0 0 0" />
      <geometry>
        <mesh
          filename="package://Urdf_ConfigFiles/meshes/LM_R_LINK.STL" />
      </geometry>
    </collision>
  </link>
  <joint
    name="LM_R_JOINT"
    type="revolute">
    <origin
      xyz="0.10465 0 0"
      rpy="3.1416 -1.5708 0" />
    <parent
      link="LM_XI_LINK" />
    <child
      link="LM_R_LINK" />
    <axis
      xyz="0 0 -1" />
    <limit
      lower="-1.5708"
      upper="1.5708"
      effort="0"
      velocity="0" />
  </joint>
  <link
    name="LM_P_LINK">
    <inertial>
      <origin
        xyz="0 0 -1.30443073877162E-18"
        rpy="0 0 0" />
      <mass
        value="5.23598775598299E-07" />
      <inertia
        ixx="5.23598775598299E-14"
        ixy="0"
        ixz="0"
        iyy="5.23598775598299E-14"
        iyz="-1.46626343100792E-72"
        izz="5.23598775598299E-14" />
    </inertial>
    <visual>
      <origin
        xyz="0 0 0"
        rpy="0 0 0" />
      <geometry>
        <mesh
          filename="package://Urdf_ConfigFiles/meshes/LM_P_LINK.STL" />
      </geometry>
      <material
        name="">
        <color
          rgba="1 1 1 1" />
      </material>
    </visual>
    <collision>
      <origin
        xyz="0 0 0"
        rpy="0 0 0" />
      <geometry>
        <mesh
          filename="package://Urdf_ConfigFiles/meshes/LM_P_LINK.STL" />
      </geometry>
    </collision>
  </link>
  <joint
    name="LM_P_JOIINT"
    type="revolute">
    <origin
      xyz="0 0 0"
      rpy="0 1.5708 0" />
    <parent
      link="LM_R_LINK" />
    <child
      link="LM_P_LINK" />
    <axis
      xyz="0 0 -1" />
    <limit
      lower="-1.5708"
      upper="1.5708"
      effort="0"
      velocity="0" />
  </joint>
  <link
    name="LM_Y_LINK">
    <inertial>
      <origin
        xyz="0 -3.3881317890172E-21 0"
        rpy="0 0 0" />
      <mass
        value="5.23598775598299E-07" />
      <inertia
        ixx="5.23598775598299E-14"
        ixy="0"
        ixz="0"
        iyy="5.23598775598299E-14"
        iyz="1.46626343100792E-72"
        izz="5.23598775598299E-14" />
    </inertial>
    <visual>
      <origin
        xyz="0 0 0"
        rpy="0 0 0" />
      <geometry>
        <mesh
          filename="package://Urdf_ConfigFiles/meshes/LM_Y_LINK.STL" />
      </geometry>
      <material
        name="">
        <color
          rgba="1 1 1 1" />
      </material>
    </visual>
    <collision>
      <origin
        xyz="0 0 0"
        rpy="0 0 0" />
      <geometry>
        <mesh
          filename="package://Urdf_ConfigFiles/meshes/LM_Y_LINK.STL" />
      </geometry>
    </collision>
  </link>
  <joint
    name="LM_Y_JOINT"
    type="revolute">
    <origin
      xyz="0 0 0"
      rpy="1.5708 0 0" />
    <parent
      link="LM_P_LINK" />
    <child
      link="LM_Y_LINK" />
    <axis
      xyz="0 0 -1" />
    <limit
      lower="-1.5708"
      upper="1.5708"
      effort="0"
      velocity="0" />
  </joint>
  <link
    name="LB_JIAN_LINK">
    <inertial>
      <origin
        xyz="0.0187543594239746 -0.000379261041653159 0.000812950580056265"
        rpy="0 0 0" />
      <mass
        value="0.006998228698532" />
      <inertia
        ixx="9.56104624157523E-07"
        ixy="-3.9369561068569E-10"
        ixz="-7.71981360439205E-11"
        iyy="6.83941781705483E-07"
        iyz="5.40143195608328E-12"
        izz="6.8461249538711E-07" />
    </inertial>
    <visual>
      <origin
        xyz="0 0 0"
        rpy="0 0 0" />
      <geometry>
        <mesh
          filename="package://Urdf_ConfigFiles/meshes/LB_JIAN_LINK.STL" />
      </geometry>
      <material
        name="">
        <color
          rgba="0.752941176470588 0.752941176470588 0.752941176470588 1" />
      </material>
    </visual>
    <collision>
      <origin
        xyz="0 0 0"
        rpy="0 0 0" />
      <geometry>
        <mesh
          filename="package://Urdf_ConfigFiles/meshes/LB_JIAN_LINK.STL" />
      </geometry>
    </collision>
  </link>
  <joint
    name="LB_JIAN_JOINT"
    type="revolute">
    <origin
      xyz="-0.077746 0.036979 0.0047"
      rpy="0 0 2.3562" />
    <parent
      link="base_link" />
    <child
      link="LB_JIAN_LINK" />
    <axis
      xyz="0 0 1" />
    <limit
      lower="-1.5708"
      upper="1.5708"
      effort="0"
      velocity="0" />
  </joint>
  <link
    name="LB_ZHOU_LINK">
    <inertial>
      <origin
        xyz="0.0212109520762893 -1.20023545821853E-05 0.00316723430021992"
        rpy="0 0 0" />
      <mass
        value="0.0234278880987742" />
      <inertia
        ixx="1.4400619370826E-06"
        ixy="-4.51031291569567E-12"
        ixz="1.20698820616244E-14"
        iyy="3.27264695060804E-06"
        iyz="-5.76430442889303E-15"
        izz="2.5543895946667E-06" />
    </inertial>
    <visual>
      <origin
        xyz="0 0 0"
        rpy="0 0 0" />
      <geometry>
        <mesh
          filename="package://Urdf_ConfigFiles/meshes/LB_ZHOU_LINK.STL" />
      </geometry>
      <material
        name="">
        <color
          rgba="0.752941176470588 0.752941176470588 0.752941176470588 1" />
      </material>
    </visual>
    <collision>
      <origin
        xyz="0 0 0"
        rpy="0 0 0" />
      <geometry>
        <mesh
          filename="package://Urdf_ConfigFiles/meshes/LB_ZHOU_LINK.STL" />
      </geometry>
    </collision>
  </link>
  <joint
    name="LB_ZHOU_JOINT"
    type="revolute">
    <origin
      xyz="0.03995 0.0047 0"
      rpy="1.5708 0 0" />
    <parent
      link="LB_JIAN_LINK" />
    <child
      link="LB_ZHOU_LINK" />
    <axis
      xyz="0 0 1" />
    <limit
      lower="-1.5708"
      upper="1.5708"
      effort="0"
      velocity="0" />
  </joint>
  <link
    name="LB_XI_LINK">
    <inertial>
      <origin
        xyz="0.0466384689069637 -7.843280032091E-05 0.000588778477363761"
        rpy="0 0 0" />
      <mass
        value="0.00724422084311933" />
      <inertia
        ixx="4.47759491534584E-07"
        ixy="-3.05207207859682E-11"
        ixz="-3.89529951404155E-10"
        iyy="3.11680934014372E-06"
        iyz="5.40136704277938E-12"
        izz="2.82563849119694E-06" />
    </inertial>
    <visual>
      <origin
        xyz="0 0 0"
        rpy="0 0 0" />
      <geometry>
        <mesh
          filename="package://Urdf_ConfigFiles/meshes/LB_XI_LINK.STL" />
      </geometry>
      <material
        name="">
        <color
          rgba="0.752941176470588 0.752941176470588 0.752941176470588 1" />
      </material>
    </visual>
    <collision>
      <origin
        xyz="0 0 0"
        rpy="0 0 0" />
      <geometry>
        <mesh
          filename="package://Urdf_ConfigFiles/meshes/LB_XI_LINK.STL" />
      </geometry>
    </collision>
  </link>
  <joint
    name="LB_XI_JOINT"
    type="revolute">
    <origin
      xyz="0.043146 0 0.004675"
      rpy="0 0 -1.5708" />
    <parent
      link="LB_ZHOU_LINK" />
    <child
      link="LB_XI_LINK" />
    <axis
      xyz="0 0 1" />
    <limit
      lower="-1.5708"
      upper="1.5708"
      effort="0"
      velocity="0" />
  </joint>
  <link
    name="LB_R_LINK">
    <inertial>
      <origin
        xyz="0 1.38777878078145E-17 -1.38777878078145E-17"
        rpy="0 0 0" />
      <mass
        value="5.23598775598299E-07" />
      <inertia
        ixx="5.23598775598299E-14"
        ixy="-1.46626343100792E-72"
        ixz="0"
        iyy="5.23598775598299E-14"
        iyz="0"
        izz="5.23598775598299E-14" />
    </inertial>
    <visual>
      <origin
        xyz="0 0 0"
        rpy="0 0 0" />
      <geometry>
        <mesh
          filename="package://Urdf_ConfigFiles/meshes/LB_R_LINK.STL" />
      </geometry>
      <material
        name="">
        <color
          rgba="1 1 1 1" />
      </material>
    </visual>
    <collision>
      <origin
        xyz="0 0 0"
        rpy="0 0 0" />
      <geometry>
        <mesh
          filename="package://Urdf_ConfigFiles/meshes/LB_R_LINK.STL" />
      </geometry>
    </collision>
  </link>
  <joint
    name="LB_R_JOINT"
    type="revolute">
    <origin
      xyz="0.10465 -5E-05 0"
      rpy="1.5708 -0.7854 -1.5708" />
    <parent
      link="LB_XI_LINK" />
    <child
      link="LB_R_LINK" />
    <axis
      xyz="0 0 -1" />
    <limit
      lower="-1.5708"
      upper="1.5708"
      effort="0"
      velocity="0" />
  </joint>
  <link
    name="LB_P_LINK">
    <inertial>
      <origin
        xyz="1.38777878078145E-17 1.38777878078145E-17 0"
        rpy="0 0 0" />
      <mass
        value="5.23598775598299E-07" />
      <inertia
        ixx="5.23598775598299E-14"
        ixy="0"
        ixz="0"
        iyy="5.23598775598299E-14"
        iyz="-1.46626343100792E-72"
        izz="5.23598775598299E-14" />
    </inertial>
    <visual>
      <origin
        xyz="0 0 0"
        rpy="0 0 0" />
      <geometry>
        <mesh
          filename="package://Urdf_ConfigFiles/meshes/LB_P_LINK.STL" />
      </geometry>
      <material
        name="">
        <color
          rgba="1 1 1 1" />
      </material>
    </visual>
    <collision>
      <origin
        xyz="0 0 0"
        rpy="0 0 0" />
      <geometry>
        <mesh
          filename="package://Urdf_ConfigFiles/meshes/LB_P_LINK.STL" />
      </geometry>
    </collision>
  </link>
  <joint
    name="LB_P_JOINT"
    type="revolute">
    <origin
      xyz="0 0 0"
      rpy="0 1.5708 0" />
    <parent
      link="LB_R_LINK" />
    <child
      link="LB_P_LINK" />
    <axis
      xyz="0 0 -1" />
    <limit
      lower="-1.5708"
      upper="1.5708"
      effort="0"
      velocity="0" />
  </joint>
  <link
    name="LB_Y_LINK">
    <inertial>
      <origin
        xyz="1.38777878078145E-17 0 -1.38777878078145E-17"
        rpy="0 0 0" />
      <mass
        value="5.23598775598299E-07" />
      <inertia
        ixx="5.23598775598299E-14"
        ixy="0"
        ixz="0"
        iyy="5.23598775598299E-14"
        iyz="1.46626343100792E-72"
        izz="5.23598775598299E-14" />
    </inertial>
    <visual>
      <origin
        xyz="0 0 0"
        rpy="0 0 0" />
      <geometry>
        <mesh
          filename="package://Urdf_ConfigFiles/meshes/LB_Y_LINK.STL" />
      </geometry>
      <material
        name="">
        <color
          rgba="1 1 1 1" />
      </material>
    </visual>
    <collision>
      <origin
        xyz="0 0 0"
        rpy="0 0 0" />
      <geometry>
        <mesh
          filename="package://Urdf_ConfigFiles/meshes/LB_Y_LINK.STL" />
      </geometry>
    </collision>
  </link>
  <joint
    name="LB_Y_JOINT"
    type="revolute">
    <origin
      xyz="0 0 0"
      rpy="1.5708 0 0" />
    <parent
      link="LB_P_LINK" />
    <child
      link="LB_Y_LINK" />
    <axis
      xyz="0 0 -1" />
    <limit
      lower="-1.5708"
      upper="1.5708"
      effort="0"
      velocity="0" />
  </joint>
  <link
    name="RB_JIAN_LINK">
    <inertial>
      <origin
        xyz="0.0187543594239746 -0.000379261041653135 0.000812950580056313"
        rpy="0 0 0" />
      <mass
        value="0.006998228698532" />
      <inertia
        ixx="9.56104624157522E-07"
        ixy="-3.93695610685717E-10"
        ixz="-7.71981360439396E-11"
        iyy="6.83941781705483E-07"
        iyz="5.40143195603111E-12"
        izz="6.8461249538711E-07" />
    </inertial>
    <visual>
      <origin
        xyz="0 0 0"
        rpy="0 0 0" />
      <geometry>
        <mesh
          filename="package://Urdf_ConfigFiles/meshes/RB_JIAN_LINK.STL" />
      </geometry>
      <material
        name="">
        <color
          rgba="0.752941176470588 0.752941176470588 0.752941176470588 1" />
      </material>
    </visual>
    <collision>
      <origin
        xyz="0 0 0"
        rpy="0 0 0" />
      <geometry>
        <mesh
          filename="package://Urdf_ConfigFiles/meshes/RB_JIAN_LINK.STL" />
      </geometry>
    </collision>
  </link>
  <joint
    name="RB_JIAN_JOINT"
    type="revolute">
    <origin
      xyz="-0.077746 -0.036979 0.0047"
      rpy="0 0 -2.3562" />
    <parent
      link="base_link" />
    <child
      link="RB_JIAN_LINK" />
    <axis
      xyz="0 0 1" />
    <limit
      lower="-1.5708"
      upper="1.5708"
      effort="0"
      velocity="0" />
  </joint>
  <link
    name="RB_ZHOU_LINK">
    <inertial>
      <origin
        xyz="0.0212109520761939 -1.20023545564949E-05 0.00316723430027723"
        rpy="0 0 0" />
      <mass
        value="0.0234278880988858" />
      <inertia
        ixx="1.44006193709275E-06"
        ixy="-4.5103100067366E-12"
        ixz="1.20744314755842E-14"
        iyy="3.27264695062257E-06"
        iyz="-5.76935427448541E-15"
        izz="2.55438959467175E-06" />
    </inertial>
    <visual>
      <origin
        xyz="0 0 0"
        rpy="0 0 0" />
      <geometry>
        <mesh
          filename="package://Urdf_ConfigFiles/meshes/RB_ZHOU_LINK.STL" />
      </geometry>
      <material
        name="">
        <color
          rgba="0.752941176470588 0.752941176470588 0.752941176470588 1" />
      </material>
    </visual>
    <collision>
      <origin
        xyz="0 0 0"
        rpy="0 0 0" />
      <geometry>
        <mesh
          filename="package://Urdf_ConfigFiles/meshes/RB_ZHOU_LINK.STL" />
      </geometry>
    </collision>
  </link>
  <joint
    name="RB_ZHOU_JOINT"
    type="revolute">
    <origin
      xyz="0.03995 0.0047 0"
      rpy="1.5708 0 0" />
    <parent
      link="RB_JIAN_LINK" />
    <child
      link="RB_ZHOU_LINK" />
    <axis
      xyz="0 0 1" />
    <limit
      lower="-1.5708"
      upper="1.5708"
      effort="0"
      velocity="0" />
  </joint>
  <link
    name="RB_XI_LINK">
    <inertial>
      <origin
        xyz="0.0466384689069637 -7.84328003208268E-05 0.000588778477363723"
        rpy="0 0 0" />
      <mass
        value="0.00724422084311934" />
      <inertia
        ixx="4.47759491534585E-07"
        ixy="-3.05207207868226E-11"
        ixz="-3.89529951404065E-10"
        iyy="3.11680934014373E-06"
        iyz="5.4013670429911E-12"
        izz="2.82563849119695E-06" />
    </inertial>
    <visual>
      <origin
        xyz="0 0 0"
        rpy="0 0 0" />
      <geometry>
        <mesh
          filename="package://Urdf_ConfigFiles/meshes/RB_XI_LINK.STL" />
      </geometry>
      <material
        name="">
        <color
          rgba="0.752941176470588 0.752941176470588 0.752941176470588 1" />
      </material>
    </visual>
    <collision>
      <origin
        xyz="0 0 0"
        rpy="0 0 0" />
      <geometry>
        <mesh
          filename="package://Urdf_ConfigFiles/meshes/RB_XI_LINK.STL" />
      </geometry>
    </collision>
  </link>
  <joint
    name="RB_XI_JOINT"
    type="revolute">
    <origin
      xyz="0.043146 0 0.004675"
      rpy="0 0 -1.5708" />
    <parent
      link="RB_ZHOU_LINK" />
    <child
      link="RB_XI_LINK" />
    <axis
      xyz="0 0 1" />
    <limit
      lower="-1.5708"
      upper="1.5708"
      effort="0"
      velocity="0" />
  </joint>
  <link
    name="RB_R_LINK">
    <inertial>
      <origin
        xyz="0 -2.77555756156289E-17 -1.38777878078145E-17"
        rpy="0 0 0" />
      <mass
        value="5.23598775598299E-07" />
      <inertia
        ixx="5.23598775598299E-14"
        ixy="-1.46626343100792E-72"
        ixz="0"
        iyy="5.23598775598299E-14"
        iyz="0"
        izz="5.23598775598299E-14" />
    </inertial>
    <visual>
      <origin
        xyz="0 0 0"
        rpy="0 0 0" />
      <geometry>
        <mesh
          filename="package://Urdf_ConfigFiles/meshes/RB_R_LINK.STL" />
      </geometry>
      <material
        name="">
        <color
          rgba="1 1 1 1" />
      </material>
    </visual>
    <collision>
      <origin
        xyz="0 0 0"
        rpy="0 0 0" />
      <geometry>
        <mesh
          filename="package://Urdf_ConfigFiles/meshes/RB_R_LINK.STL" />
      </geometry>
    </collision>
  </link>
  <joint
    name="RB_R_JOINT"
    type="revolute">
    <origin
      xyz="0.10465 -5E-05 0"
      rpy="1.5708 0.7854 -1.5708" />
    <parent
      link="RB_XI_LINK" />
    <child
      link="RB_R_LINK" />
    <axis
      xyz="0 0 -1" />
    <limit
      lower="-1.5708"
      upper="1.5708"
      effort="0"
      velocity="0" />
  </joint>
  <link
    name="RB_P_LINK">
    <inertial>
      <origin
        xyz="1.38777878078145E-17 0 0"
        rpy="0 0 0" />
      <mass
        value="5.23598775598299E-07" />
      <inertia
        ixx="5.23598775598299E-14"
        ixy="0"
        ixz="0"
        iyy="5.23598775598299E-14"
        iyz="-1.46626343100792E-72"
        izz="5.23598775598299E-14" />
    </inertial>
    <visual>
      <origin
        xyz="0 0 0"
        rpy="0 0 0" />
      <geometry>
        <mesh
          filename="package://Urdf_ConfigFiles/meshes/RB_P_LINK.STL" />
      </geometry>
      <material
        name="">
        <color
          rgba="1 1 1 1" />
      </material>
    </visual>
    <collision>
      <origin
        xyz="0 0 0"
        rpy="0 0 0" />
      <geometry>
        <mesh
          filename="package://Urdf_ConfigFiles/meshes/RB_P_LINK.STL" />
      </geometry>
    </collision>
  </link>
  <joint
    name="RB_P_JOINT"
    type="revolute">
    <origin
      xyz="0 0 0"
      rpy="0 1.5708 0" />
    <parent
      link="RB_R_LINK" />
    <child
      link="RB_P_LINK" />
    <axis
      xyz="0 0 -1" />
    <limit
      lower="-1.5708"
      upper="1.5708"
      effort="0"
      velocity="0" />
  </joint>
  <link
    name="RB_Y_LINK">
    <inertial>
      <origin
        xyz="1.38777878078145E-17 0 0"
        rpy="0 0 0" />
      <mass
        value="5.23598775598299E-07" />
      <inertia
        ixx="5.23598775598299E-14"
        ixy="0"
        ixz="0"
        iyy="5.23598775598299E-14"
        iyz="1.46626343100792E-72"
        izz="5.23598775598299E-14" />
    </inertial>
    <visual>
      <origin
        xyz="0 0 0"
        rpy="0 0 0" />
      <geometry>
        <mesh
          filename="package://Urdf_ConfigFiles/meshes/RB_Y_LINK.STL" />
      </geometry>
      <material
        name="">
        <color
          rgba="1 1 1 1" />
      </material>
    </visual>
    <collision>
      <origin
        xyz="0 0 0"
        rpy="0 0 0" />
      <geometry>
        <mesh
          filename="package://Urdf_ConfigFiles/meshes/RB_Y_LINK.STL" />
      </geometry>
    </collision>
  </link>
  <joint
    name="RB_Y_JOINT"
    type="revolute">
    <origin
      xyz="0 0 0"
      rpy="1.5708 0 0" />
    <parent
      link="RB_P_LINK" />
    <child
      link="RB_Y_LINK" />
    <axis
      xyz="0 0 -1" />
    <limit
      lower="-1.5708"
      upper="1.5708"
      effort="0"
      velocity="0" />
  </joint>
</robot>